<?xml version="1.0" ?>
<robot name="puck" xmlns:xacro="http://www.ros.org/wiki/xacro">
  <material name="white">
    <color rgba="1 1 1 1"/>
  </material>
  <material name="black">
    <color rgba="0 0 0 1"/>
  </material>
  <material name="red">
    <color rgba="1 0 0 1"/>
  </material>
  <material name="blue">
    <color rgba="0 0 1 1"/>
  </material>
  <link name="root">
    <inertial>
      <mass value="0.1"/>
      <inertia ixx="0.00016666666666666672" ixy="0" ixz="0" iyy="0.00016666666666666672" iyz="0" izz="0.00016666666666666672"/>
    </inertial>
  </link>
  <joint name="root2lift" type="prismatic">
    <parent link="root"/>
    <child link="lift"/>
    <origin rpi="0 0 0" xyz="0 0 0"/>
    <axis xyz="0 0 1"/>
    <limit lower="0" upper="0.4"/>
  </joint>
  <link name="lift"/>
  <joint name="lift2right" type="prismatic">
    <parent link="lift"/>
    <child link="right"/>
    <origin rpi="0 0 0" xyz="0.2 0 0.05"/>
    <axis xyz="1 0 0"/>
    <limit lower="-0.2" upper="-0.05"/>
  </joint>
  <link name="right">
    <visual>
      <origin rpy="0 0 0" xyz="0 0 0"/>
      <geometry>
        <box size="0.1 0.30000000000000004 0.1"/>
      </geometry>
      <material name="blue"/>
    </visual>
    <collision>
      <origin rpy="0 0 0" xyz="0 0 0"/>
      <geometry>
        <box size="0.1 0.30000000000000004 0.1"/>
      </geometry>
    </collision>
    <inertial>
      <mass value="0.1"/>
      <inertia ixx="0.0008333333333333336" ixy="0" ixz="0" iyy="0.00016666666666666672" iyz="0" izz="0.00016666666666666672"/>
    </inertial>
    <contact>
      <lateral_friction value=".5"/>
      <rolling_friction value="0.0"/>
      <stiffness value="30000"/>
      <damping value="1000"/>
    </contact>
  </link>
  <joint name="root2left" type="prismatic">
    <parent link="lift"/>
    <child link="left"/>
    <origin rpi="0 0 0" xyz="-0.2 0 0.05"/>
    <axis xyz="1 0 0"/>
    <limit lower="0.05" upper="0.2"/>
  </joint>
  <link name="left">
    <visual>
      <origin rpy="0 0 0" xyz="0 0 0"/>
      <geometry>
        <box size="0.1 0.30000000000000004 0.1"/>
      </geometry>
      <material name="blue"/>
    </visual>
    <collision>
      <origin rpy="0 0 0" xyz="0 0 0"/>
      <geometry>
        <box size="0.1 0.30000000000000004 0.1"/>
      </geometry>
    </collision>
    <inertial>
      <mass value="0.1"/>
      <inertia ixx="0.0008333333333333336" ixy="0" ixz="0" iyy="0.00016666666666666672" iyz="0" izz="0.00016666666666666672"/>
    </inertial>
    <contact>
      <lateral_friction value=".5"/>
      <rolling_friction value="0.0"/>
      <stiffness value="30000"/>
      <damping value="1000"/>
    </contact>
  </link>
</robot>
